package com.gtladd.gtladditions.common.machine.multiblock.structure

import com.gregtechceu.gtceu.api.pattern.FactoryBlockPattern
import com.gregtechceu.gtceu.api.pattern.util.RelativeDirection

object MultiBlockStructureB {
    @JvmField
    val TIME_SPACE_DISTORTER_STRUCTURE: FactoryBlockPattern = FactoryBlockPattern.start()
        .aisle("                                                                             ", "                                                                             ", "                                                                             ", "                                                                             ", "                                                                             ", "                                                                             ", "                                                                             ", "                                                                             ", "                                                                             ", "                                                                             ", "                                                                             ", "                                                                             ", "                                AAAAAAAAAAAAA                                ", "                                                                             ", "                                                                             ", "                                                                             ", "                                                                             ", "                                                                             ", "                                                                             ", "                                                                             ", "                                                                             ", "                                                                             ", "                                                                             ", "                                                                             ", "                                                                             ")
        .aisle("                                                                             ", "                                                                             ", "                                                                             ", "                                                                             ", "                                                                             ", "                                                                             ", "                                                                             ", "                                                                             ", "                                                                             ", "                                                                             ", "                                                                             ", "                                AAAAAAAAAAAAA                                ", "                               ACCCCCCCCCCCCCA                               ", "                                AAAAAAAAAAAAA                                ", "                                                                             ", "                                                                             ", "                                                                             ", "                                                                             ", "                                                                             ", "                                                                             ", "                                                                             ", "                                                                             ", "                                                                             ", "                                                                             ", "                                                                             ")
        .aisle("                                                                             ", "                                                                             ", "                                                                             ", "                                                                             ", "                                                                             ", "                                                                             ", "                                                                             ", "                                                                             ", "                                                                             ", "                                                                             ", "                                AAAAAAAAAAAAA                                ", "                               ACCCCCCCCCCCCCA                               ", "                            CCCCDDDDDDDDDDDDDCCCC                            ", "                               ACCCCCCCCCCCCCA                               ", "                                AAAAAAAAAAAAA                                ", "                                                                             ", "                                                                             ", "                                                                             ", "                                                                             ", "                                                                             ", "                                                                             ", "                                                                             ", "                                                                             ", "                                                                             ", "                                                                             ")
        .aisle("                                                                             ", "                                                                             ", "                                                                             ", "                                                                             ", "                                                                             ", "                                                                             ", "                                                                             ", "                                                                             ", "                                                                             ", "                                AAAAAAAAAAAAA                                ", "                               ACCCCCCCCCCCCCA                               ", "                            CCCCDDDDDDDDDDDDDCCCC                            ", "                         CCCDDDDDDDDDDDDDDDDDDDDDCCC                         ", "                            CCCCDDDDDDDDDDDDDCCCC                            ", "                               ACCCCCCCCCCCCCA                               ", "                                AAAAAAAAAAAAA                                ", "                                                                             ", "                                                                             ", "                                                                             ", "                                                                             ", "                                                                             ", "                                                                             ", "                                                                             ", "                                                                             ", "                                                                             ")
        .aisle("                                                                             ", "                                                                             ", "                                                                             ", "                                                                             ", "                                                                             ", "                                                                             ", "                                                                             ", "                                                                             ", "                                                                             ", "                               AAA         AAA                               ", "                            CCCCCCAAAAAAAAACCCCCC                            ", "                         CCCDDDDDDCCCCCCCCCDDDDDDCCC                         ", "                       CCDDDDDDDDDDDDDDDDDDDDDDDDDDDCC                       ", "                         CCCDDDDDDCCCCCCCCCDDDDDDCCC                         ", "                            CCCCCCAAAAAAAAACCCCCC                            ", "                               AAA         AAA                               ", "                                                                             ", "                                                                             ", "                                                                             ", "                                                                             ", "                                                                             ", "                                                                             ", "                                                                             ", "                                                                             ", "                                                                             ")
        .aisle("                                                                             ", "                                                                             ", "                                                                             ", "                                                                             ", "                                                                             ", "                                                                             ", "                                                                             ", "                                                                             ", "                                                                             ", "                                                                             ", "                         CCCCCCAAA         AAACCCCCC                         ", "                       CCDDDDDDCCCAAAAAAAAACCCDDDDDDCC                       ", "                   EECCDDDDDDDDDDDCCCCCCCCCDDDDDDDDDDDCCEE                   ", "                       CCDDDDDDCCCAAAAAAAAACCCDDDDDDCC                       ", "                         CCCCCCAAA         AAACCCCCC                         ", "                                                                             ", "                                                                             ", "                                                                             ", "                                                                             ", "                                                                             ", "                                                                             ", "                                                                             ", "                                                                             ", "                                                                             ", "                                                                             ")
        .aisle("                                                                             ", "                                                                             ", "                                                                             ", "                                                                             ", "                                                                             ", "                                                                             ", "                                                                             ", "                                                                             ", "                                                                             ", "                                                                             ", "                       CCC                         CCC                       ", "                   EECCDDDCCCCCAAA         AAACCCCCDDDCCEE                   ", "                  ECCDDDDDDDDDDCCCAAAAAAAAACCCDDDDDDDDDDCCE                  ", "                   EECCDDDCCCCCAAA         AAACCCCCDDDCCEE                   ", "                       CCC                         CCC                       ", "                                                                             ", "                                                                             ", "                                                                             ", "                                                                             ", "                                                                             ", "                                                                             ", "                                                                             ", "                                                                             ", "                                                                             ", "                                                                             ")
        .aisle("                                                                             ", "                                                                             ", "                                                                             ", "                                                                             ", "                                                                             ", "                                                                             ", "                                                                             ", "                                                                             ", "                                                                             ", "                                                                             ", "                   EECC                               CCEE                   ", "                  ECCDDCCC                         CCCDDCCE                  ", "                EECDDDDDDDCCCCCAAA         AAACCCCCDDDDDDDCEE                ", "                  ECCDDCCC                         CCCDDCCE                  ", "                   EECC                               CCEE                   ", "                                                                             ", "                                                                             ", "                                                                             ", "                                                                             ", "                                                                             ", "                                                                             ", "                                                                             ", "                                                                             ", "                                                                             ", "                                                                             ")
        .aisle("                                                                             ", "                                                                             ", "                                                                             ", "                                                                             ", "                                                                             ", "                                                                             ", "                                                                             ", "                                                                             ", "                                                                             ", "                   EE                                   EE                   ", "                  ECC                                   CCE                  ", "                EECDDCC                               CCDDCEE                ", "               ECCDDDDDCCCFG                     GFCCCDDDDDCCE               ", "                EECDDCC                               CCDDCEE                ", "                  ECC                                   CCE                  ", "                   EE                                   EE                   ", "                                                                             ", "                                                                             ", "                                                                             ", "                                                                             ", "                                                                             ", "                                                                             ", "                                                                             ", "                                                                             ", "                                                                             ")
        .aisle("                                                                             ", "                                                                             ", "                                                                             ", "                                                                             ", "                                                                             ", "                                                                             ", "                                                                             ", "                                                                             ", "                                                                             ", "                  EE                                     EE                  ", "                EECCE                                   ECCEE                ", "               ECCDDC                                   CDDCCE               ", "              ECDDDDDCCFFFG                       GFFFCCDDDDDCE              ", "               ECCDDC                                   CDDCCE               ", "                EECCE                                   ECCEE                ", "                  EE                                     EE                  ", "                                                                             ", "                                                                             ", "                                                                             ", "                                                                             ", "                                                                             ", "                                                                             ", "                                                                             ", "                                                                             ", "                                                                             ")
        .aisle("                                                                             ", "                                                                             ", "                                                                             ", "                                                                             ", "                                                                             ", "                                                                             ", "                                                                             ", "                                                                             ", "                                                                             ", "                EE                                         EE                ", "               ECCEE                                     EECCE               ", "              ECDDCCE                                   ECCDDCE              ", "             ECDDDDDCFFFFG                         GFFFFCDDDDDCE             ", "              ECDDCCE                                   ECCDDCE              ", "               ECCEE                                     EECCE               ", "                EE                                         EE                ", "                                                                             ", "                                                                             ", "                                                                             ", "                                                                             ", "                                                                             ", "                                                                             ", "                                                                             ", "                                                                             ", "                                                                             ")
        .aisle("                                                                             ", "                                                                             ", "                                                                             ", "                                                                             ", "                                                                             ", "                                                                             ", "                                                                             ", "                                                                             ", "                                                                             ", "               EE                                           EE               ", "              ECCE                                         ECCE              ", "             ECDDCEE                                     EECDDCE             ", "            ECDDDDCCFFFFG            HHH            GFFFFCCDDDDCE            ", "             ECDDCEE                                     EECDDCE             ", "              ECCE                                         ECCE              ", "               EE                                           EE               ", "                                                                             ", "                                                                             ", "                                                                             ", "                                                                             ", "                                                                             ", "                                                                             ", "                                                                             ", "                                                                             ", "                                                                             ")
        .aisle("                                                                             ", "                                                                             ", "                                                                             ", "                                                                             ", "                                                                             ", "                                                                             ", "                                                                             ", "                                                                             ", "                                                                             ", "              EE                                             EE              ", "             ECCE                                           ECCE             ", "            ECDDCE                                         ECDDCE            ", "           ECDDDDCFFFFFG           HH   HH           GFFFFFCDDDDCE           ", "            ECDDCE                                         ECDDCE            ", "             ECCE                                           ECCE             ", "              EE                                             EE              ", "                                                                             ", "                                                                             ", "                                                                             ", "                                                                             ", "                                                                             ", "                                                                             ", "                                                                             ", "                                                                             ", "                                                                             ")
        .aisle("                                                                             ", "                                                                             ", "                                                                             ", "                                                                             ", "                                                                             ", "                                                                             ", "                                                                             ", "                                                                             ", "                                                                             ", "             EE                                               EE             ", "            ECCE                                             ECCE            ", "           ECDDCE                                           ECDDCE           ", "          ECDDDDCFFFFFFG          H   I   H          GFFFFFFCDDDDCE          ", "           ECDDCE                     I                     ECDDCE           ", "            ECCE                      I                      ECCE            ", "             EE                                               EE             ", "                                                                             ", "                                                                             ", "                                                                             ", "                                                                             ", "                                                                             ", "                                                                             ", "                                                                             ", "                                                                             ", "                                                                             ")
        .aisle("                                                                             ", "                                                                             ", "                                                                             ", "                                                                             ", "                                                                             ", "                                                                             ", "                                                                             ", "                                                                             ", "                                                                             ", "            EE                                                 EE            ", "           ECCE                       I                       ECCE           ", "          ECDDCE                      I                      ECDDCE          ", "         ECDDDDCFFFFFFG           H  IJI  H           GFFFFFFCDDDDCE         ", "          ECDDCE                     IJI                     ECDDCE          ", "           ECCE                      IJI                      ECCE           ", "            EE                        I                        EE            ", "                                      I                                      ", "                                                                             ", "                                                                             ", "                                                                             ", "                                                                             ", "                                                                             ", "                                                                             ", "                                                                             ", "                                                                             ")
        .aisle("                                                                             ", "                                                                             ", "                                                                             ", "                                                                             ", "                                                                             ", "                                                                             ", "                                                                             ", "                                                                             ", "                                      I                                      ", "           EE                         I                         EE           ", "          ECCE                       IJI                       ECCE          ", "         ECDDCE                      IJI                      ECDDCE         ", "        ECDDDDCFFFFFFFG          H  IJJJI  H          GFFFFFFFCDDDDCE        ", "         ECDDCE                     IJJJI                     ECDDCE         ", "          ECCE                      IJJJI                      ECCE          ", "           EE                        IJI                        EE           ", "                                     IJI                                     ", "                                      I                                      ", "                                      I                                      ", "                                                                             ", "                                                                             ", "                                                                             ", "                                                                             ", "                                                                             ", "                                                                             ")
        .aisle("                                                                             ", "                                                                             ", "                                                                             ", "                                                                             ", "                                                                             ", "                                                                             ", "                                      I                                      ", "                                      I                                      ", "                                     IJI                                     ", "          EE                         IJI                         EE          ", "         ECCE                       IJ JI                       ECCE         ", "        ECDDCE                      IJ JI                      ECDDCE        ", "       ECDDDDCFFFFFFFG           H IJJJJJI H           GFFFFFFFCDDDDCE       ", "        ECDDCE                     IJJJJJI                     ECDDCE        ", "         ECCE                      IJJJJJI                      ECCE         ", "          EE                        IJ JI                        EE          ", "                                    IJ JI                                    ", "                                     IJI                                     ", "                                     IJI                                     ", "                                      I                                      ", "                                      I                                      ", "                                                                             ", "                                                                             ", "                                                                             ", "                                                                             ")
        .aisle("                                                                             ", "                                                                             ", "                                                                             ", "                                                                             ", "                                                                             ", "                                                                             ", "                                                                             ", "                                                                             ", "                                      I                                      ", "          E                           I                           E          ", "         ECE                         IJI                         ECE         ", "        ECDCE                        IJI                        ECDCE        ", "       ECDDDCFFFFFFFFK          GH  IJJJI  HG          KFFFFFFFFCDDDCE       ", "        ECDCE                       IJJJI                       ECDCE        ", "         ECE                        IJJJI                        ECE         ", "          E                          IJI                          E          ", "                                     IJI                                     ", "                                      I                                      ", "                                      I                                      ", "                                                                             ", "                                                                             ", "                                                                             ", "                                                                             ", "                                                                             ", "                                                                             ")
        .aisle("                                                                             ", "                                                                             ", "                                                                             ", "                                                                             ", "                                                                             ", "                                                                             ", "                                                                             ", "                                                                             ", "                                                                             ", "         E                                                         E         ", "        ECE                           I                           ECE        ", "       ECDCE         C                I                C         ECDCE       ", "      ECDDDCFFFFFFFFKLK        G  H  IJI  H  G        KLKFFFFFFFFCDDDCE      ", "       ECDCE         C               IJI               C         ECDCE       ", "        ECE                          IJI                          ECE        ", "         E                            I                            E         ", "                                      I                                      ", "                                                                             ", "                    MMM                               MMM                    ", "                                                                             ", "                                                                             ", "                                                                             ", "                                                                             ", "                                                                             ", "                                                                             ")
        .aisle("                                                                             ", "                                                                             ", "                                                                             ", "                                                                             ", "                                                                             ", "                                                                             ", "                                                                             ", "                                                                             ", "                                                                             ", "        EE                                                         EE        ", "       ECCE                                                       ECCE       ", "      ECDDCE        CCC                               CCC        ECDDCE      ", "     ECDDDDCFFFFFFFKLNLK     GG   H   I   H   GG     KLNLKFFFFFFFCDDDDCE     ", "      ECDDCE        CCC               I               CCC        ECDDCE      ", "       ECCE          C                I                C          ECCE       ", "        EE                                                         EE        ", "                                                                             ", "                    MMM                               MMM                    ", "                   M   M                             M   M                   ", "                   O   O                             O   O                   ", "                                                                             ", "                                                                             ", "                                                                             ", "                                                                             ", "                                                                             ")
        .aisle("                                                                             ", "                                                                             ", "                                                                             ", "                                                                             ", "                                                                             ", "                                                                             ", "                                                                             ", "                                                                             ", "                                                                             ", "        E                                                           E        ", "       ECE          PPP                               PPP          ECE       ", "      ECDCE        CCCCC                             CCCCC        ECDCE      ", "     ECDDDCFFFFFFFKLQQQLK  GG      HH   HH      GG  KLQQQLKFFFFFFFCDDDCE     ", "      ECDCE        CCRCC                             CCRCC        ECDCE      ", "       ECE          CNC                               CNC          ECE       ", "        E           CRC                               CRC           E        ", "                    MMM                               MMM                    ", "                   M   M                             M   M                   ", "                  M     M                           M     M                  ", "                                                                             ", "                    O O                               O O                    ", "                                                                             ", "                                                                             ", "                                                                             ", "                                                                             ")
        .aisle("                                                                             ", "                                                                             ", "                                                                             ", "                                                                             ", "                                                                             ", "                                                                             ", "                                                                             ", "                                                                             ", "                                                                             ", "                                                                             ", "       C            PNP                               PNP            C       ", "      CDC         CCCCCCC                           CCCCCCC         CDC      ", "     CDDDCFFFFFFGKLNQQQNLKG          HHH          GKLNQQQNLKGFFFFFFCDDDC     ", "      CDC         CCRSRCC                           CCRSRCC         CDC      ", "       C           CNRNC                             CNRNC           C       ", "                    RRR                               RRR                    ", "                    MRM                               MRM                    ", "                   M G M                             M G M                   ", "                  M  G  M                           M  G  M                  ", "                     G                                 G                     ", "                     G                                 G                     ", "                     G                                 G                     ", "                                                                             ", "                                                                             ", "                                                                             ")
        .aisle("                                                                             ", "                                                                             ", "                                                                             ", "                                                                             ", "                                                                             ", "                                                                             ", "                                                                             ", "                                                                             ", "                                                                             ", "                                                                             ", "       C            PPP                               PPP            C       ", "      CDC          CCCCC                             CCCCC          CDC      ", "     CDDDCFFFFGG  KLQQQLKFFGG                   GGFFKLQQQLK  GGFFFFCDDDC     ", "      CDC          CCRCC                             CCRCC          CDC      ", "       C            CNC                               CNC            C       ", "                    CRC                               CRC                    ", "                    MMM                               MMM                    ", "                   M   M                             M   M                   ", "                  M     M                           M     M                  ", "                                                                             ", "                    O O                               O O                    ", "                                                                             ", "                                                                             ", "                                                                             ", "                                                                             ")
        .aisle("                                                                             ", "                                                                             ", "                                                                             ", "                                                                             ", "                                                                             ", "                                                                             ", "                                                                             ", "                                                                             ", "                                                                             ", "                                                                             ", "      C                                                               C      ", "     CDC            CCC                               CCC            CDC     ", "    CDDDCFFFGG     KLNLKFFFFFGG               GGFFFFFKLNLK     GGFFFCDDDC    ", "     CDC            CCC                               CCC            CDC     ", "      C              C                                 C              C      ", "                                                                             ", "                                                                             ", "                    MMM                               MMM                    ", "                   M   M                             M   M                   ", "                   O   O                             O   O                   ", "                                                                             ", "                                                                             ", "                                                                             ", "                                                                             ", "                                                                             ")
        .aisle("                                                                             ", "                                                                             ", "                                                                             ", "                                                                             ", "                                                                             ", "                                                                             ", "                                                                             ", "                                                                             ", "                                                                             ", "                                                                             ", "      C                                                               C      ", "     CDC             C                                 C             CDC     ", "    CDDDCFFG        KLKFFFFFFFFG             GFFFFFFFFKLK        GFFCDDDC    ", "     CDC             C                                 C             CDC     ", "      C                                                               C      ", "                                                                             ", "                                                                             ", "                                                                             ", "                    MMM                               MMM                    ", "                                                                             ", "                                                                             ", "                                                                             ", "                                                                             ", "                                                                             ", "                                                                             ")
        .aisle("                                                                             ", "                                                                             ", "                                                                             ", "                                                                             ", "                                                                             ", "                                                                             ", "                                                                             ", "                                                                             ", "                                                                             ", "                                                                             ", "     CC                                                               CC     ", "    CDDC                                                             CDDC    ", "   CDDDDCFG          KFFFFFFFFFFG           GFFFFFFFFFFK          GFCDDDDC   ", "    CDDC                                                             CDDC    ", "     CC                                                               CC     ", "                                                                             ", "                                                                             ", "                                                                             ", "                                                                             ", "                                                                             ", "                                                                             ", "                                                                             ", "                                                                             ", "                                                                             ", "                                                                             ")
        .aisle("                                                                             ", "                                                                             ", "                                                                             ", "                                                                             ", "                                                                             ", "                                                                             ", "                                                                             ", "                                                                             ", "                                                                             ", "                                                                             ", "     C                                                                 C     ", "    CDC                                                               CDC    ", "   CDDDCFG           GFFFFFFFFFFFG         GFFFFFFFFFFFG           GFCDDDC   ", "    CDC                                                               CDC    ", "     C                                                                 C     ", "                                                                             ", "                                                                             ", "                                                                             ", "                                                                             ", "                                                                             ", "                                                                             ", "                                                                             ", "                                                                             ", "                                                                             ", "                                                                             ")
        .aisle("                                                                             ", "                                                                             ", "                                                                             ", "                                                                             ", "                                                                             ", "                                                                             ", "                                                                             ", "                                                                             ", "                                                                             ", "                                                                             ", "     C                                                                 C     ", "    CDC                                                               CDC    ", "   CDDDCG           G GFFFFFFFFFFFG       GFFFFFFFFFFFG G           GCDDDC   ", "    CDC                                                               CDC    ", "     C                                                                 C     ", "                                                                             ", "                                                                             ", "                                                                             ", "                                                                             ", "                                                                             ", "                                                                             ", "                                                                             ", "                                                                             ", "                                                                             ", "                                                                             ")
        .aisle("                                                                             ", "                                                                             ", "                                                                             ", "                                                                             ", "                                                                             ", "                                                                             ", "                                                                             ", "                                                                             ", "                                                                             ", "                                                                             ", "    CC                                                                 CC    ", "   CDDC                                                               CDDC   ", "  CDDDDC            G GFFFFFFFFFFFFG     GFFFFFFFFFFFFG G            CDDDDC  ", "   CDDC                                                               CDDC   ", "    CC                                                                 CC    ", "                                                                             ", "                                                                             ", "                                                                             ", "                                                                             ", "                                                                             ", "                                                                             ", "                                                                             ", "                                                                             ", "                                                                             ", "                                                                             ")
        .aisle("                                                                             ", "                                                                             ", "                                                                             ", "                                                                             ", "                                                                             ", "                                                                             ", "                                                                             ", "                                                                             ", "                                                                             ", "                                                                             ", "    CC                                                                 CC    ", "   CDDC                                                               CDDC   ", "  CDDDDC           G   GFFFFFFFFFFFFG   GFFFFFFFFFFFFG   G           CDDDDC  ", "   CDDC                                                               CDDC   ", "    CC                                                                 CC    ", "                                                                             ", "                                                                             ", "                                                                             ", "                                                                             ", "                                                                             ", "                                                                             ", "                                                                             ", "                                                                             ", "                                                                             ", "                                                                             ")
        .aisle("                                    KKKKK                                    ", "                                      T                                      ", "                                     T                                       ", "                                    T                                        ", "                                                                             ", "                                                                             ", "                                                                             ", "                                                                             ", "                                                                             ", "                                                                             ", "    CC                                  T                              CC    ", "   CDDC                                T                              CDDC   ", "  CDDDDC           G   GFFFFFFFFFFFFG T GFFFFFFFFFFFFG   G           CDDDDC  ", "   CDDC                              T                                CDDC   ", "    CC                              T                                  CC    ", "                                                                             ", "                                                                             ", "                                                                             ", "                                                                             ", "                                                                             ", "                                                                             ", "                                        T                                    ", "                                       T                                     ", "                                      T                                      ", "                                    KKKKK                                    ")
        .aisle("                                  KKFFFFFKK                                  ", "                                                                             ", "                                                                             ", "                                                                             ", "                                   T                                         ", "                                  T                                          ", "                                                                             ", "                                                                             ", "                                          T                                  ", "    A                                    T                              A    ", "   ACA                                                                 ACA   ", "  ACDCA                                                               ACDCA  ", " ACDDDCA          G     GFFFFFFFFFFFFG GFFFFFFFFFFFFG     G          ACDDDCA ", "  ACDCA                                                               ACDCA  ", "   ACA                                                                 ACA   ", "    A                              T                                    A    ", "                                  T                                          ", "                                                                             ", "                                                                             ", "                                          T                                  ", "                                         T                                   ", "                                                                             ", "                                                                             ", "                                                                             ", "                                  KKFFFFFKK                                  ")
        .aisle("                                 KPPFFFFFPPK                                 ", "                                                                             ", "                                                                             ", "                                                                             ", "                                                                             ", "                                                                             ", "                                 T                                           ", "                                           T                                 ", "                                                                             ", "   AA                                                                   AA   ", "  ACCA                                                                 ACCA  ", " ACDDCA                                                               ACDDCA ", "ACDDDDCA         G       GFFFFFFFFFFFG GFFFFFFFFFFFG       G         ACDDDDCA", " ACDDCA                                                               ACDDCA ", "  ACCA                                                                 ACCA  ", "   AA                                                                   AA   ", "                                                                             ", "                                 T                                           ", "                                           T                                 ", "                                                                             ", "                                                                             ", "                                                                             ", "                                                                             ", "                                                                             ", "                                 KPPFFFFFPPK                                 ")
        .aisle("                                KFPFPFPFPFPFK                                ", "                                                                             ", "                                                                             ", "                                                                             ", "                                                                             ", "                                                                             ", "                U                           T               U                ", "                 U              T                            U               ", "                                                                             ", "   AA                                                                   AA   ", "  ACCA                              CCCCC                              ACCA  ", " ACDDCA        U                    CCCCC                  U          ACDDCA ", "ACDDDDCA       GUG        GFFFFFFFFFCCCCCFFFFFFFFFG        GU        ACDDDDCA", " ACDDCA          U                  CCCCC                    U        ACDDCA ", "  ACCA                              BBBBB                              ACCA  ", "   AA                                                                   AA   ", "                                                                             ", "               U                            T              U                 ", "                U               T                           U                ", "                                                                             ", "                                                                             ", "                                                                             ", "                                                                             ", "                                                                             ", "                                KFPFPFFFPFPFK                                ")
        .aisle("                               KFFPFPPFPPFPFFK                               ", "                                                                             ", "                                                                             ", "                                                                             ", "                                                                             ", "                                     VVV     T                               ", "                                     RRR                                     ", "                                     RRR                                     ", "                  U            T     RRR                      U              ", "   A                                 RRR                                 A   ", "  ACA         U                    CCRRRCC                U             ACA  ", " ACDCA                             CCRRRCC                             ACDCA ", "ACDDDCA      GG   GG       GFFFFFFFCCRRRCCFFFFFFFG                    ACDDDCA", " ACDCA                             CCRRRCC                             ACDCA ", "  ACA             U                BBRRRBB                    U         ACA  ", "   A                                 RRR                                 A   ", "              U                      RRR     T            U                  ", "                                     RRR                                     ", "                                     RRR                                     ", "                               T     RRR                                     ", "                                     VVV                                     ", "                                                                             ", "                                                                             ", "                                                                             ", "                               KFFPFPPFPPFPFFK                               ")
        .aisle("                               KFFPPFFFFFPPFFK                               ", "                                                                             ", "                                                                             ", "                                                                             ", "                                     III     T                               ", "                                    VVVVV                                    ", "                                    RLLLR                                    ", "                                    R   R                                    ", "                                    R   R                                    ", "   A         U     U           T    R   R                U     U         A   ", "  ACA                             CCR   RCC                             ACA  ", " ACDCA          I                 CCR   RCC                 I          ACDCA ", "ACDDDCA     G   I   G       GFFFFFCCR   RCCFFFFFG           I         ACDDDCA", " ACDCA          I                 CCR   RCC                 I          ACDCA ", "  ACA                             BBR   RBB                             ACA  ", "   A         U     U                R   R    T           U     U         A   ", "                                    R   R                                    ", "                                    R   R                                    ", "                                    R   R                                    ", "                                    RLLLR                                    ", "                               T    VVVVV                                    ", "                                     III                                     ", "                                                                             ", "                                     III                                     ", "                               KFFPPFFPFFPPFFK                               ")
        .aisle("                              KFFPPFFFFFFFPPFFK                              ", "                                                                             ", "                                                                             ", "                                     III      T                              ", "                                    IJJJI                                    ", "                                   VVVVVVV                                   ", "                                   RL   LR                                   ", "                                   R     R                                   ", "            U                      R     R              U                    ", "   A            I                  R     R                  I            A   ", "  ACA           I   U         T  CCR     RCC                I   U       ACA  ", " ACDCA         IJI               CCR     RCC               IJI         ACDCA ", "ACDDDCA     G  IJI  G        GGFFCCR  W  RCCFFGG           IJI        ACDDDCA", " ACDCA         IJI               CCR     RCC               IJI         ACDCA ", "  ACA       U   I                BBR     RBB  T         U   I           ACA  ", "   A            I                  R     R                  I            A   ", "                    U              R     R                      U            ", "                                   R     R                                   ", "                                   R     R                                   ", "                                   RL   LR                                   ", "                                   VVVVVVV                                   ", "                              T     IJJJI                                    ", "                                     III                                     ", "                                    IJJJI                                    ", "                              KFFPPFFFFFFFPPFFK                              ")
        .aisle("                              KFPFPFFNXNFFPFPFK                              ", "                                                                             ", "                                     III      T                              ", "                                    IJJJI                                    ", "                                   IJ   JI                                   ", "                                  VVVVVVVVV                                  ", "                                  RL  G  LR                                  ", "           U    I                 R       R            U    I                ", "                I                 R       R                 I                ", "   A           IJI                R       R                IJI           A   ", "  ACA          IJI               CR       RC               IJI          ACA  ", " ACDCA        IJJJI  U        T  CR   W   RC              IJJJI  U     ACDCA ", "ACDDDCA    G  IJJJI  G         GGCR  WYW  RCGG            IJJJI       ACDDDCA", " ACDCA     U  IJJJI              CR   W   RC  T        U  IJJJI        ACDCA ", "  ACA          IJI               BR       RB               IJI          ACA  ", "   A           IJI                R       R                IJI           A   ", "                I                 R       R                 I                ", "                I    U            R       R                 I    U           ", "                                  R       R                                  ", "                                  RL  G  LR                                  ", "                                  VVVVVVVVV                                  ", "                                   IJQQQJI                                   ", "                              T     IJJJI                                    ", "                                   IJRRRJI                                   ", "                              KFPFPFFNXNFFPFPFK                              ")
        .aisle("                              KPFFPFFXZXFFPFFPK                              ", "                              T       I       T                              ", "                                     IJI                                     ", "                                    IJ JI                                    ", "                                   IJ   JI                                   ", "                I                 VVVVZVVVV                 I                ", "           U    I    U            RL GGG LR            U    I    U           ", "               IJI                R   X   R                IJI               ", "               IJI                R       R                IJI               ", "   A          IJJJI               R       R               IJJJI          A   ", "  ACA         IJJJI              CR   W   RC              IJJJI         ACA  ", " ACDCA       IJJJJJI             CR  WYW  RC             IJJJJJI       ACDCA ", "ACDDDCA    U IJJJJJI U        T  CR WY[YW RC  T        U IJJJJJI U    ACDDDCA", " ACDCA       IJJJJJI             CR  WYW  RC             IJJJJJI       ACDCA ", "  ACA         IJJJI              BR   W   RB              IJJJI         ACA  ", "   A          IJJJI               R       R               IJJJI          A   ", "               IJI                R       R                IJI               ", "               IJI                R       R                IJI               ", "           U    I    U            R   X   R            U    I    U           ", "                I                 RL GGG LR                 I                ", "                                  VVVVZVVVV                                  ", "                                   IJQQQJI                                   ", "                                    IJSJI                                    ", "                              T    IJRRRJI    T                              ", "                              KPFFPFFXRXFFPFFPK                              ")
        .aisle("                              KFPFPFFNXNFFPFPFK                              ", "                                                                             ", "                              T      III                                     ", "                                    IJJJI                                    ", "                                   IJ   JI                                   ", "                                  VVVVVVVVV                                  ", "                                  RL  G  LR                                  ", "                I    U            R       R                 I    U           ", "                I                 R       R                 I                ", "   A           IJI                R       R                IJI           A   ", "  ACA          IJI               CR       RC               IJI          ACA  ", " ACDCA     U  IJJJI              CR   W   RC  T        U  IJJJI        ACDCA ", "ACDDDCA    G  IJJJI  G         GGCR  WYW  RCGG            IJJJI       ACDDDCA", " ACDCA        IJJJI  U        T  CR   W   RC              IJJJI  U     ACDCA ", "  ACA          IJI               BR       RB               IJI          ACA  ", "   A           IJI                R       R                IJI           A   ", "                I                 R       R                 I                ", "           U    I                 R       R            U    I                ", "                                  R       R                                  ", "                                  RL  G  LR                                  ", "                                  VVVVVVVVV                                  ", "                                   IJQQQJI                                   ", "                                    IJJJI     T                              ", "                                   IJRRRJI                                   ", "                              KFPFPFFNXNFFPFPFK                              ")
        .aisle("                              KFFPPFFFFFFFPPFFK                              ", "                                                                             ", "                                                                             ", "                              T      III                                     ", "                                    IJJJI                                    ", "                                   VVVVVVV                                   ", "                                   RL   LR                                   ", "                                   R     R                                   ", "                    U              R     R                      U            ", "   A            I                  R     R                  I            A   ", "  ACA       U   I                CCR     RCC  T         U   I           ACA  ", " ACDCA         IJI               CCR     RCC               IJI         ACDCA ", "ACDDDCA     G  IJI  G        GGFFCCR  W  RCCFFGG           IJI        ACDDDCA", " ACDCA         IJI               CCR     RCC               IJI         ACDCA ", "  ACA           I   U         T  BBR     RBB                I   U       ACA  ", "   A            I                  R     R                  I            A   ", "            U                      R     R              U                    ", "                                   R     R                                   ", "                                   R     R                                   ", "                                   RL   LR                                   ", "                                   VVVVVVV                                   ", "                                    IJJJI     T                              ", "                                     III                                     ", "                                    IJJJI                                    ", "                              KFFPPFFFFFFFPPFFK                              ")
        .aisle("                               KFFPPFFFFFPPFFK                               ", "                                                                             ", "                                                                             ", "                                                                             ", "                               T     III                                     ", "                                    VVVVV                                    ", "                                    RLLLR                                    ", "                                    R   R                                    ", "                                    R   R                                    ", "   A         U     U                R   R    T           U     U         A   ", "  ACA                             CCR   RCC                             ACA  ", " ACDCA          I                 CCR   RCC                 I          ACDCA ", "ACDDDCA     G   I   G       GFFFFFCCR   RCCFFFFFG           I         ACDDDCA", " ACDCA          I                 CCR   RCC                 I          ACDCA ", "  ACA                             BBR   RBB                             ACA  ", "   A         U     U           T    R   R                U     U         A   ", "                                    R   R                                    ", "                                    R   R                                    ", "                                    R   R                                    ", "                                    RLLLR                                    ", "                                    VVVVV    T                               ", "                                     III                                     ", "                                                                             ", "                                     III                                     ", "                               KFFPPFFPFFPPFFK                               ")
        .aisle("                               KFFPFPPFPPFPFFK                               ", "                                                                             ", "                                                                             ", "                                                                             ", "                                                                             ", "                               T     VVV                                     ", "                                     RRR                                     ", "                                     RRR                                     ", "              U                      RRR     T            U                  ", "   A                                 RRR                                 A   ", "  ACA             U                CCRRRCC                    U         ACA  ", " ACDCA                             CCRRRCC                             ACDCA ", "ACDDDCA      GG   GG       GFFFFFFFCCRRRCCFFFFFFFG                    ACDDDCA", " ACDCA                             CCRRRCC                             ACDCA ", "  ACA         U                    BBRRRBB                U             ACA  ", "   A                                 RRR                                 A   ", "                  U            T     RRR                      U              ", "                                     RRR                                     ", "                                     RRR                                     ", "                                     RRR     T                               ", "                                     VVV                                     ", "                                                                             ", "                                                                             ", "                                                                             ", "                               KFFPFPPFPPFPFFK                               ")
        .aisle("                                KFPFPFPFPFPFK                                ", "                                                                             ", "                                                                             ", "                                                                             ", "                                                                             ", "                                                                             ", "                U               T                           U                ", "               U                            T              U                 ", "                                                                             ", "   AA                                                                   AA   ", "  ACCA                              CCCCC                              ACCA  ", " ACDDCA          U                  CCCCC                    U        ACDDCA ", "ACDDDDCA       GUG        GFFFFFFFFFCCCCCFFFFFFFFFG        GU        ACDDDDCA", " ACDDCA        U                    CCCCC                  U          ACDDCA ", "  ACCA                              BB~BB                              ACCA  ", "   AA                                                                   AA   ", "                                                                             ", "                 U              T                            U               ", "                U                           T               U                ", "                                                                             ", "                                                                             ", "                                                                             ", "                                                                             ", "                                                                             ", "                                KFPFPFFFPFPFK                                ")
        .aisle("                                 KPPFFFFFPPK                                 ", "                                                                             ", "                                                                             ", "                                                                             ", "                                                                             ", "                                                                             ", "                                           T                                 ", "                                 T                                           ", "                                                                             ", "   AA                                                                   AA   ", "  ACCA                                                                 ACCA  ", " ACDDCA                                                               ACDDCA ", "ACDDDDCA         G       GFFFFFFFFFFFG GFFFFFFFFFFFG       G         ACDDDDCA", " ACDDCA                                                               ACDDCA ", "  ACCA                                                                 ACCA  ", "   AA                                                                   AA   ", "                                                                             ", "                                           T                                 ", "                                 T                                           ", "                                                                             ", "                                                                             ", "                                                                             ", "                                                                             ", "                                                                             ", "                                 KPPFFFFFPPK                                 ")
        .aisle("                                  KKFFFFFKK                                  ", "                                                                             ", "                                                                             ", "                                                                             ", "                                         T                                   ", "                                          T                                  ", "                                                                             ", "                                                                             ", "                                  T                                          ", "    A                              T                                    A    ", "   ACA                                                                 ACA   ", "  ACDCA                                                               ACDCA  ", " ACDDDCA          G     GFFFFFFFFFFFFG GFFFFFFFFFFFFG     G          ACDDDCA ", "  ACDCA                                                               ACDCA  ", "   ACA                                                                 ACA   ", "    A                                    T                              A    ", "                                          T                                  ", "                                                                             ", "                                                                             ", "                                  T                                          ", "                                   T                                         ", "                                                                             ", "                                                                             ", "                                                                             ", "                                  KKFFFFFKK                                  ")
        .aisle("                                    KKKKK                                    ", "                                      T                                      ", "                                       T                                     ", "                                        T                                    ", "                                                                             ", "                                                                             ", "                                                                             ", "                                                                             ", "                                                                             ", "                                                                             ", "    CC                              T                                  CC    ", "   CDDC                              T                                CDDC   ", "  CDDDDC           G   GFFFFFFFFFFFFG T GFFFFFFFFFFFFG   G           CDDDDC  ", "   CDDC                                T                              CDDC   ", "    CC                                  T                              CC    ", "                                                                             ", "                                                                             ", "                                                                             ", "                                                                             ", "                                                                             ", "                                                                             ", "                                    T                                        ", "                                     T                                       ", "                                      T                                      ", "                                    KKKKK                                    ")
        .aisle("                                                                             ", "                                                                             ", "                                                                             ", "                                                                             ", "                                                                             ", "                                                                             ", "                                                                             ", "                                                                             ", "                                                                             ", "                                                                             ", "    CC                                                                 CC    ", "   CDDC                                                               CDDC   ", "  CDDDDC           G   GFFFFFFFFFFFFG   GFFFFFFFFFFFFG   G           CDDDDC  ", "   CDDC                                                               CDDC   ", "    CC                                                                 CC    ", "                                                                             ", "                                                                             ", "                                                                             ", "                                                                             ", "                                                                             ", "                                                                             ", "                                                                             ", "                                                                             ", "                                                                             ", "                                                                             ")
